<?xml version="1.0" ?>
<mujoco model="arm">
    <compiler angle="degree" inertiafromgeom="true"/>
    <size njmax="500" nconmax="100"/>
    <asset>
        <mesh name="base_link" file="base_link.STL"/>
        <mesh name="base" file="base.STL"/>
        <mesh name="lower" file="lower.STL"/>
        <mesh name="upper" file="upper.STL"/>
    </asset>
    <worldbody>
        <geom type="mesh" rgba="0.792157 0.819608 0.933333 1" mesh="base_link" pos="-.45 .75 -.6"/>
        <body name="base" pos="0 0 0" quat="1 1 0 0">
            <joint name="base" pos="0 0 0" axis="0 1 0" damping="10"/>
            <geom type="mesh" rgba="0.792157 0.819608 0.933333 1" mesh="base"/>
            <body name="lower" pos="0 0.4 0">
                <joint name="lower" pos="0 0 0" axis="1 0 0" range="-55 55" limited="true" damping="10"/>
                <geom type="mesh" rgba="0.792157 0.819608 0.933333 1" mesh="lower"/>
                <body name="upper" pos="0 1.5 0">
                    <camera name="camera" pos="0 0 0" quat="0 0 0 1"/>
                    <joint name="upper" pos="0 0 0" axis="1 0 0" range="-95 95" limited="true" damping="10"/>
                    <geom type="mesh" rgba="0.792157 0.819608 0.933333 1" mesh="upper"/>
                </body>
            </body>
        </body>
        <!-- <body name="target" pos=".0 0 3">
            <joint type="free" damping="0.007" name="target" />
            <geom name="target" pos="0 0 0" rgba="0.3 0.9 0.2 1" size="0.03" type="sphere" />
        </body> -->
    </worldbody>
    <actuator>
        <motor gear="100" name="lower" joint="lower" ctrlrange="-100 100" ctrllimited="true"/>
        <motor gear="100" name="upper" joint="upper" ctrlrange="-100 100" ctrllimited="true"/>
        <motor gear="100" name="base" joint="base" ctrlrange="-100 100" ctrllimited="true" />
    </actuator>
</mujoco>