<!-- Created using my conversion script found in utils/conversions.py -->
<!-- <?xml version="1.0"?> -->
<mujoco model="arm">
    <compiler angle="degree" inertiafromgeom="true"/>
    <option integrator="RK4" timestep="0.01"/>
    <!-- <size njmax="500" nconmax="100"/> -->
    <asset>
        <mesh name="base_link" file="base_link.STL"/>
        <mesh name="base" file="base.STL"/>
        <mesh name="lower" file="lower.STL"/>
        <mesh name="upper" file="upper.STL"/>
    </asset>
    <worldbody>
        <body name="base" pos="0 0 0" quat="1 1 0 0">
            <joint name="base" pos="0 0 0" axis="0 1 0" damping="100" frictionloss="50"/>
            <geom type="mesh" rgba="0.792157 0.819608 0.933333 1" mesh="base"/>
            <body name="lower" pos="0 0.4 0">
                <joint name="lower" pos="0 0 0" axis="1 0 0" range="-90 90" limited="true" damping="100" frictionloss="50"/>
                <geom type="mesh" rgba="0.792157 0.819608 0.933333 1" mesh="lower"/>
                <body name="upper" pos="0 1.5 0">
                    <camera name="camera" pos="0 0 0" quat="0 0 0 1"/>
                    <joint name="upper" pos="0 0 0" axis="1 0 0" range="-95 95" limited="true" damping="100" frictionloss="50"/>
                    <geom type="mesh" rgba="0.792157 0.819608 0.933333 1" mesh="upper"/>
                </body>
            </body>
        </body>
        <body name="target" pos="0 0 0">
            <joint name="target" type="free" damping="0"/>
            <geom type="sphere" rgba="0.792157 0.819608 0.933333 1" size="0.1"/>
        </body>
    </worldbody>
    <actuator>
        <motor gear="100" name="lower" joint="lower" ctrlrange="-250 250" ctrllimited="true"/>
        <motor gear="100" name="upper" joint="upper" ctrlrange="-250 250" ctrllimited="true"/>
        <motor gear="100" name="base" joint="base" ctrlrange="-250 250" ctrllimited="true" />
    </actuator>
    <sensor>

    </sensor>
</mujoco>